#VRML_SIM R2019a utf8
WorldInfo {
}
Viewpoint {
  orientation -0.07202986723119136 -0.963852124531357 -0.2565166276541275 2.6366257900615957
  position -0.8807346220123775 1.9609516591329057 -1.4901742176194124
}
TexturedBackground {
}
TexturedBackgroundLight {
}
Floor {
}
DEF OMNI_WHEELS Robot {
  translation 0.1 0.06 0.1
  children [
    DEF SOLID1 Solid {
      children [
        DEF WHEEL1 HingeJoint {
          jointParameters HingeJointParameters {
            axis 0 0 1
            anchor 0 0 0.1
          }
          device [
            RotationalMotor {
              name "wheel1"
              maxVelocity 52.4
              maxTorque 0.59312
            }
            PositionSensor {
              name "encoder1"
            }
          ]
          endPoint Solid {
            translation 0 0 0.1
            rotation 0 0 1 0
            children [
              DEF sr1 HingeJoint {
                jointParameters HingeJointParameters {
                  anchor 0 0.05 0.02
                }
                endPoint Solid {
                  translation 0 0.05 0.02
                  rotation 1 0 0 0
                  children [
                    DEF r1 Transform {
                      rotation 0 0 1 1.5708
                      children [
                        DEF SMALL_WHEEL_SHAPE Shape {
                          appearance PBRAppearance {
                            baseColor 1 0.752941 0.796078
                            roughness 1
                            metalness 0
                          }
                          geometry Cylinder {
                            height 0.02
                            radius 0.01
                          }
                        }
                      ]
                    }
                  ]
                  name "sr1"
                  boundingObject USE r1
                  physics Physics {
                    density -1
                    mass 0.1
                  }
                }
              }
              DEF sr2 HingeJoint {
                jointParameters HingeJointParameters {
                  axis 0.707107 0.707107 0
                  anchor -0.03535 0.03535 0.02
                }
                endPoint Solid {
                  translation -0.03535 0.03535 0.02
                  rotation 0.7071067811865476 0.7071067811865476 0 0
                  children [
                    DEF r2 Transform {
                      rotation 0 0 1 2.27
                      children [
                        USE SMALL_WHEEL_SHAPE
                      ]
                    }
                  ]
                  name "sr2"
                  boundingObject USE r2
                  physics Physics {
                    density -1
                    mass 0.1
                  }
                }
              }
              DEF sr3 HingeJoint {
                jointParameters HingeJointParameters {
                  anchor 0 -0.05 0.02
                }
                endPoint Solid {
                  translation 0 -0.05 0.02
                  rotation 1 0 0 0
                  children [
                    DEF r3 Transform {
                      rotation 0 0 1 1.5708
                      children [
                        USE SMALL_WHEEL_SHAPE
                      ]
                    }
                  ]
                  name "sr3"
                  boundingObject USE r3
                  physics Physics {
                    density -1
                    mass 0.1
                  }
                }
              }
              DEF sr4 HingeJoint {
                jointParameters HingeJointParameters {
                  axis 0.707107 0.707107 0
                  anchor 0.03535 -0.03535 0.02
                }
                endPoint Solid {
                  translation 0.03535 -0.03535 0.02
                  rotation 0.7071067811865476 0.7071067811865476 0 0
                  children [
                    DEF r4 Transform {
                      rotation 0 0 1 2.27
                      children [
                        USE SMALL_WHEEL_SHAPE
                      ]
                    }
                  ]
                  name "sr4"
                  boundingObject USE r4
                  physics Physics {
                    density -1
                    mass 0.1
                  }
                }
              }
              DEF sr5 HingeJoint {
                jointParameters HingeJointParameters {
                  axis 0 1 0
                  anchor -0.05 0 0.02
                }
                endPoint Solid {
                  translation -0.05 0 0.02
                  children [
                    DEF r5 Transform {
                      children [
                        USE SMALL_WHEEL_SHAPE
                      ]
                    }
                  ]
                  name "sr5"
                  boundingObject USE r5
                  physics Physics {
                    density -1
                    mass 0.1
                  }
                }
              }
              DEF sr6 HingeJoint {
                jointParameters HingeJointParameters {
                  axis 0 1 0
                  anchor 0.05 0 0.02
                }
                endPoint Solid {
                  translation 0.05 0 0.02
                  children [
                    DEF r6 Transform {
                      children [
                        USE SMALL_WHEEL_SHAPE
                      ]
                    }
                  ]
                  name "sr6"
                  boundingObject USE r6
                  physics Physics {
                    density -1
                    mass 0.1
                  }
                }
              }
              DEF sr7 HingeJoint {
                jointParameters HingeJointParameters {
                  axis -0.707107 0.707107 0
                  anchor -0.03535 -0.03535 0.02
                }
                endPoint Solid {
                  translation -0.03535 -0.03535 0.02
                  rotation -0.7071067811865476 0.7071067811865476 0 0
                  children [
                    DEF r7 Transform {
                      rotation 0 0 1 0.76
                      children [
                        USE SMALL_WHEEL_SHAPE
                      ]
                    }
                  ]
                  name "sr7"
                  boundingObject USE r7
                  physics Physics {
                    density -1
                    mass 0.1
                  }
                }
              }
              DEF sr8 HingeJoint {
                jointParameters HingeJointParameters {
                  axis -0.707107 0.707107 0
                  anchor 0.03535 0.03535 0.02
                }
                endPoint Solid {
                  translation 0.03535 0.03535 0.02
                  rotation -0.7071067811865476 0.7071067811865476 0 0
                  children [
                    DEF r8 Transform {
                      rotation 0 0 1 0.76
                      children [
                        USE SMALL_WHEEL_SHAPE
                      ]
                    }
                  ]
                  name "sr8"
                  boundingObject USE r8
                  physics Physics {
                    density -1
                    mass 0.1
                  }
                }
              }
              DEF WHEEL_TRANS Transform {
                translation 0 0 0.02
                rotation 1 0 0 1.5708
                children [
                  DEF WHEEL_SHAPE Shape {
                    appearance PBRAppearance {
                      baseColor 0.678431 0.847059 0.901961
                      roughness 1
                      metalness 0
                    }
                    geometry Cylinder {
                      height 0.02
                      radius 0.05
                      subdivision 20
                    }
                  }
                ]
              }
            ]
            boundingObject Transform {
              translation 0 0 0.02
              rotation 1 0 0 1.5708
              children [
                DEF wheel1 Shape {
                  appearance PBRAppearance {
                    baseColor 0.8 0.8 0.8
                    transparency 0.12999999523162842
                    roughness 1
                    metalness 0
                    emissiveColor 0 1 0
                  }
                  geometry Cylinder {
                    height 0.02
                    radius 0.05
                  }
                }
              ]
            }
            physics Physics {
            }
          }
        }
      ]
      name "wheel1"
      boundingObject DEF DUMMY Sphere {
        radius 0.01
      }
      physics Physics {
      }
    }
    DEF SOLID2 Solid {
      rotation 0 1 0 2.09
      children [
        DEF WHEEL2 HingeJoint {
          jointParameters HingeJointParameters {
            axis 0 0 1
            anchor 0 0 0.1
          }
          device [
            RotationalMotor {
              name "wheel2"
              maxVelocity 52.4
              maxTorque 0.5931
            }
          ]
          endPoint Solid {
            translation 0 0 0.1
            rotation 0 0 1 0.00240580999995935
            children [
              DEF sr1 HingeJoint {
                jointParameters HingeJointParameters {
                  anchor 0 0.05 0.02
                }
                endPoint Solid {
                  translation 0 0.05 0.02
                  rotation 1 0 0 0
                  children [
                    USE r1
                  ]
                  name "sr1"
                  boundingObject USE r1
                  physics Physics {
                    density -1
                    mass 0.1
                  }
                }
              }
              DEF sr2 HingeJoint {
                jointParameters HingeJointParameters {
                  axis 0.707107 0.707107 0
                  anchor -0.03535 0.03535 0.02
                }
                endPoint Solid {
                  translation -0.03535 0.03535 0.02
                  rotation 0.7071067811865476 0.7071067811865476 0 0
                  children [
                    USE r2
                  ]
                  name "sr2"
                  boundingObject USE r2
                  physics Physics {
                    density -1
                    mass 0.1
                  }
                }
              }
              DEF sr3 HingeJoint {
                jointParameters HingeJointParameters {
                  anchor 0 -0.05 0.02
                }
                endPoint Solid {
                  translation 0 -0.05 0.02
                  rotation 1 0 0 0
                  children [
                    USE r3
                  ]
                  name "sr3"
                  boundingObject USE r3
                  physics Physics {
                    density -1
                    mass 0.1
                  }
                }
              }
              DEF sr4 HingeJoint {
                jointParameters HingeJointParameters {
                  axis 0.707107 0.707107 0
                  anchor 0.03535 -0.03535 0.02
                }
                endPoint Solid {
                  translation 0.03535 -0.03535 0.02
                  rotation 0.7071067811865476 0.7071067811865476 0 0
                  children [
                    USE r4
                  ]
                  name "sr4"
                  boundingObject USE r4
                  physics Physics {
                    density -1
                    mass 0.1
                  }
                }
              }
              DEF sr5 HingeJoint {
                jointParameters HingeJointParameters {
                  axis 0 1 0
                  anchor -0.05 0 0.02
                }
                endPoint Solid {
                  translation -0.05 0 0.02
                  children [
                    USE r5
                  ]
                  name "sr5"
                  boundingObject USE r5
                  physics Physics {
                    density -1
                    mass 0.1
                  }
                }
              }
              DEF sr6 HingeJoint {
                jointParameters HingeJointParameters {
                  axis 0 1 0
                  anchor 0.05 0 0.02
                }
                endPoint Solid {
                  translation 0.05 0 0.02
                  children [
                    USE r6
                  ]
                  name "sr6"
                  boundingObject USE r6
                  physics Physics {
                    density -1
                    mass 0.1
                  }
                }
              }
              DEF sr7 HingeJoint {
                jointParameters HingeJointParameters {
                  axis -0.707107 0.707107 0
                  anchor -0.03535 -0.03535 0.02
                }
                endPoint Solid {
                  translation -0.03535 -0.03535 0.02
                  rotation -0.7071067811865476 0.7071067811865476 0 0
                  children [
                    USE r7
                  ]
                  name "sr7"
                  boundingObject USE r7
                  physics Physics {
                    density -1
                    mass 0.1
                  }
                }
              }
              DEF sr8 HingeJoint {
                jointParameters HingeJointParameters {
                  axis -0.707107 0.707107 0
                  anchor 0.03535 0.03535 0.02
                }
                endPoint Solid {
                  translation 0.03535 0.03535 0.02
                  rotation -0.7071067811865476 0.7071067811865476 0 0
                  children [
                    USE r8
                  ]
                  name "sr8"
                  boundingObject USE r8
                  physics Physics {
                    density -1
                    mass 0.1
                  }
                }
              }
              USE WHEEL_TRANS
            ]
            boundingObject Transform {
              translation 0 0 0.02
              rotation 1 0 0 1.5708
              children [
                DEF wheel1 Shape {
                  appearance PBRAppearance {
                    baseColor 0.8 0.8 0.8
                    transparency 0.12999999523162842
                    roughness 1
                    metalness 0
                    emissiveColor 0 1 0
                  }
                  geometry Cylinder {
                    height 0.02
                    radius 0.05
                  }
                }
              ]
            }
            physics Physics {
            }
          }
        }
      ]
      name "wheel2"
      boundingObject USE DUMMY
      physics Physics {
      }
    }
    DEF SOLID3 Solid {
      rotation 0 1 0 4.18
      children [
        DEF WHEEL3 HingeJoint {
          jointParameters HingeJointParameters {
            axis 0 0 1
            anchor 0 0 0.1
          }
          device [
            RotationalMotor {
              name "wheel3"
              maxVelocity 52.4
              maxTorque 0.5931
            }
          ]
          endPoint Solid {
            translation 0 0 0.1
            rotation 0 0 1 0.0039094400000208316
            children [
              DEF sr1 HingeJoint {
                jointParameters HingeJointParameters {
                  anchor 0 0.05 0.02
                }
                endPoint Solid {
                  translation 0 0.05 0.02
                  rotation 1 0 0 0
                  children [
                    USE r1
                  ]
                  name "sr1"
                  boundingObject USE r1
                  physics Physics {
                    density -1
                    mass 0.1
                  }
                }
              }
              DEF sr2 HingeJoint {
                jointParameters HingeJointParameters {
                  axis 0.707107 0.707107 0
                  anchor -0.03535 0.03535 0.02
                }
                endPoint Solid {
                  translation -0.03535 0.03535 0.02
                  rotation 0.7071067811865476 0.7071067811865476 0 0
                  children [
                    USE r2
                  ]
                  name "sr2"
                  boundingObject USE r2
                  physics Physics {
                    density -1
                    mass 0.1
                  }
                }
              }
              DEF sr3 HingeJoint {
                jointParameters HingeJointParameters {
                  anchor 0 -0.05 0.02
                }
                endPoint Solid {
                  translation 0 -0.05 0.02
                  rotation 1 0 0 0
                  children [
                    USE r3
                  ]
                  name "sr3"
                  boundingObject USE r3
                  physics Physics {
                    density -1
                    mass 0.1
                  }
                }
              }
              DEF sr4 HingeJoint {
                jointParameters HingeJointParameters {
                  axis 0.707107 0.707107 0
                  anchor 0.03535 -0.03535 0.02
                }
                endPoint Solid {
                  translation 0.03535 -0.03535 0.02
                  rotation 0.7071067811865476 0.7071067811865476 0 0
                  children [
                    USE r4
                  ]
                  name "sr4"
                  boundingObject USE r4
                  physics Physics {
                    density -1
                    mass 0.1
                  }
                }
              }
              DEF sr5 HingeJoint {
                jointParameters HingeJointParameters {
                  axis 0 1 0
                  anchor -0.05 0 0.02
                }
                endPoint Solid {
                  translation -0.05 0 0.02
                  children [
                    USE r5
                  ]
                  name "sr5"
                  boundingObject USE r5
                  physics Physics {
                    density -1
                    mass 0.1
                  }
                }
              }
              DEF sr6 HingeJoint {
                jointParameters HingeJointParameters {
                  axis 0 1 0
                  anchor 0.05 0 0.02
                }
                endPoint Solid {
                  translation 0.05 0 0.02
                  children [
                    USE r6
                  ]
                  name "sr6"
                  boundingObject USE r6
                  physics Physics {
                    density -1
                    mass 0.1
                  }
                }
              }
              DEF sr7 HingeJoint {
                jointParameters HingeJointParameters {
                  axis -0.707107 0.707107 0
                  anchor -0.03535 -0.03535 0.02
                }
                endPoint Solid {
                  translation -0.03535 -0.03535 0.02
                  rotation -0.7071067811865476 0.7071067811865476 0 0
                  children [
                    USE r7
                  ]
                  name "sr7"
                  boundingObject USE r7
                  physics Physics {
                    density -1
                    mass 0.1
                  }
                }
              }
              DEF sr8 HingeJoint {
                jointParameters HingeJointParameters {
                  axis -0.707107 0.707107 0
                  anchor 0.03535 0.03535 0.02
                }
                endPoint Solid {
                  translation 0.03535 0.03535 0.02
                  rotation -0.7071067811865476 0.7071067811865476 0 0
                  children [
                    USE r8
                  ]
                  name "sr8"
                  boundingObject USE r8
                  physics Physics {
                    density -1
                    mass 0.1
                  }
                }
              }
              USE WHEEL_TRANS
            ]
            boundingObject Transform {
              translation 0 0 0.02
              rotation 1 0 0 1.5708
              children [
                DEF wheel1 Shape {
                  appearance PBRAppearance {
                    baseColor 0.8 0.8 0.8
                    transparency 0.12999999523162842
                    roughness 1
                    metalness 0
                    emissiveColor 0 1 0
                  }
                  geometry Cylinder {
                    height 0.02
                    radius 0.05
                  }
                }
              ]
            }
            physics Physics {
            }
          }
        }
      ]
      name "wheel3"
      boundingObject USE DUMMY
      physics Physics {
      }
    }
    DEF BODY_TRANS Transform {
      translation 0 0.03 0
      children [
        Shape {
          appearance PBRAppearance {
            baseColor 0.8666666666666667 0.5098039215686274 0.5098039215686274
            roughness 1
            metalness 0
          }
          geometry Cylinder {
            height 0.15
            radius 0.1
            subdivision 18
          }
        }
      ]
    }
    DistanceSensor {
      translation 0.05851242852873024 0.10999999999999999 0.08447111875588056
      rotation 0 1 0 5.586
      children [
        Shape {
          appearance PBRAppearance {
            baseColor 0.1803921568627451 0.20392156862745098 0.21176470588235294
          }
          geometry Box {
            size 0.02 0.01 0.01
          }
        }
      ]
      name "distance_right"
      lookupTable [
        0 0 0
        0.02 0 0
        5 1660 0
      ]
      resolution 1
    }
    DistanceSensor {
      translation 0.10394882018188648 0.10999999999999999 0.012776666310737846
      rotation 0 1 0 5.7595
      children [
        Shape {
          appearance PBRAppearance {
            baseColor 0.1803921568627451 0.20392156862745098 0.21176470588235294
          }
          geometry Box {
            size 0.02 0.01 0.01
          }
        }
      ]
      name "distance_left"
      lookupTable [
        0 0 0
        0.02 0 0
        5 1660 0
      ]
      resolution 1
    }
  ]
  boundingObject USE BODY_TRANS
  physics Physics {
  }
  controller "u3_exam_Zamudio_Shadeen"
}
Solid {
  translation 0.5823542148823653 0.13999999999999996 0.7846708993130961
  rotation 0 1 0 2.6179937475821395
  children [
    Shape {
      appearance PBRAppearance {
        baseColor 0.1803921568627451 0.20392156862745098 0.21176470588235294
      }
      geometry DEF OBS_1 Box {
        size 0.01 0.4 0.3
      }
    }
  ]
  name "solid(5)"
  boundingObject USE OBS_1
}
Solid {
  translation 1.4462515072323912 0.13999999999999996 0.6483570398919425
  rotation 0 1 0 2.6179937475821395
  children [
    Shape {
      appearance PBRAppearance {
        baseColor 0.1803921568627451 0.20392156862745098 0.21176470588235294
      }
      geometry DEF OBS_1 Box {
        size 0.01 0.4 0.3
      }
    }
  ]
  name "solid(1)"
  boundingObject USE OBS_1
}
Solid {
  translation 1.525603845209388 0.13999999999999996 1.4909145788514988
  rotation 0 1 0 2.6179937475821395
  children [
    Shape {
      appearance PBRAppearance {
        baseColor 0.1803921568627451 0.20392156862745098 0.21176470588235294
      }
      geometry DEF OBS_1 Box {
        size 0.01 0.4 0.3
      }
    }
  ]
  name "solid(2)"
  boundingObject USE OBS_1
}
Solid {
  translation 2.2738793514356703 0.13999999999999996 1.41486349876847
  rotation 0 1 0 2.6179937475821395
  children [
    Shape {
      appearance PBRAppearance {
        baseColor 0.1803921568627451 0.20392156862745098 0.21176470588235294
      }
      geometry DEF OBS_1 Box {
        size 0.01 0.4 0.3
      }
    }
  ]
  name "solid(3)"
  boundingObject USE OBS_1
}
Solid {
  translation 2.1828023091452846 0.13999999999999996 2.089741519075572
  rotation 0 -1 0 4.712389126777033
  children [
    Shape {
      appearance PBRAppearance {
        baseColor 0.1803921568627451 0.20392156862745098 0.21176470588235294
      }
      geometry DEF OBS_1 Box {
        size 0.01 0.4 0.3
      }
    }
  ]
  name "solid(4)"
  boundingObject USE OBS_1
}
Solid {
  translation 2.395289436045557 0.13999999999999996 2.004574946304483
  rotation 0 1 0 2.6179937475821395
  children [
    Shape {
      appearance PBRAppearance {
        baseColor 0.1803921568627451 0.20392156862745098 0.21176470588235294
      }
      geometry DEF OBS_1 Box {
        size 0.01 0.4 0.3
      }
    }
  ]
  name "solid(6)"
  boundingObject USE OBS_1
}
Solid {
  translation 1.6493344083564134 0.13999999999999996 2.3071323793943694
  rotation 0 -1 0 4.712389126777033
  children [
    Shape {
      appearance PBRAppearance {
        baseColor 0.1803921568627451 0.20392156862745098 0.21176470588235294
      }
      geometry DEF OBS_1 Box {
        size 0.01 0.4 0.3
      }
    }
  ]
  name "solid(7)"
  boundingObject USE OBS_1
}
Solid {
  translation 1.919334408356408 0.13999999999999996 2.307132418920308
  rotation 0 -1 0 4.712389126777033
  children [
    Shape {
      appearance PBRAppearance {
        baseColor 0.1803921568627451 0.20392156862745098 0.21176470588235294
      }
      geometry DEF OBS_1 Box {
        size 0.01 0.4 0.3
      }
    }
  ]
  name "solid(17)"
  boundingObject USE OBS_1
}
Solid {
  translation 1.331129335226317 0.13999999999999996 2.2677541158426946
  rotation 0 -1 0 5.235987900777033
  children [
    Shape {
      appearance PBRAppearance {
        baseColor 0.1803921568627451 0.20392156862745098 0.21176470588235294
      }
      geometry DEF OBS_1 Box {
        size 0.01 0.4 0.3
      }
    }
  ]
  name "solid(8)"
  boundingObject USE OBS_1
}
Solid {
  translation 0.27314243548408906 0.13999999999999996 1.9802410910861379
  rotation 0 -1 0 5.235987900777033
  children [
    Shape {
      appearance PBRAppearance {
        baseColor 0.1803921568627451 0.20392156862745098 0.21176470588235294
      }
      geometry DEF OBS_1 Box {
        size 0.01 0.4 0.3
      }
    }
  ]
  name "solid(9)"
  boundingObject USE OBS_1
}
Solid {
  translation 0.14645128063139493 0.13999999999999996 1.8446496507553563
  rotation 0 1 0 0.5235986132229661
  children [
    Shape {
      appearance PBRAppearance {
        baseColor 0.1803921568627451 0.20392156862745098 0.21176470588235294
      }
      geometry DEF OBS_1 Box {
        size 0.01 0.4 0.3
      }
    }
  ]
  name "solid(10)"
  boundingObject USE OBS_1
}
Solid {
  translation -0.039862620848088226 0.13999999999999996 1.4225214911000827
  rotation 0 -1 0 5.759586711993522
  children [
    Shape {
      appearance PBRAppearance {
        baseColor 0.1803921568627451 0.20392156862745098 0.21176470588235294
      }
      geometry DEF OBS_1 Box {
        size 0.01 0.4 0.3
      }
    }
  ]
  name "solid(11)"
  boundingObject USE OBS_1
}
Solid {
  translation -0.07335618975093562 0.13999999999999996 0.964316408096598
  rotation 0 -1 0 0.5235989719935213
  children [
    Shape {
      appearance PBRAppearance {
        baseColor 0.1803921568627451 0.20392156862745098 0.21176470588235294
      }
      geometry DEF OBS_1 Box {
        size 0.01 0.4 0.3
      }
    }
  ]
  name "solid(18)"
  boundingObject USE OBS_1
}
Solid {
  translation 0.4687665713431579 0.13999999999999996 -0.23918853799807993
  rotation 0 1 0 5.497786966222966
  children [
    Shape {
      appearance PBRAppearance {
        baseColor 0.1803921568627451 0.20392156862745098 0.21176470588235294
      }
      geometry DEF OBS_1 Box {
        size 0.01 0.4 0.3
      }
    }
  ]
  name "solid(12)"
  boundingObject USE OBS_1
}
Solid {
  translation 0.3414873281299886 0.13999999999999996 -0.11190933998409652
  rotation 0 1 0 5.497786966222966
  children [
    Shape {
      appearance PBRAppearance {
        baseColor 0.1803921568627451 0.20392156862745098 0.21176470588235294
      }
      geometry DEF OBS_1 Box {
        size 0.01 0.4 0.3
      }
    }
  ]
  name "solid(19)"
  boundingObject USE OBS_1
}
Solid {
  translation 0.8262951655122347 0.13999999999999996 -0.2791627223607758
  rotation 0 -1 0 4.974188552136207
  children [
    Shape {
      appearance PBRAppearance {
        baseColor 0.1803921568627451 0.20392156862745098 0.21176470588235294
      }
      geometry DEF OBS_1 Box {
        size 0.01 0.4 0.5
      }
    }
  ]
  name "solid(13)"
  boundingObject USE OBS_1
}
Solid {
  translation 1.137422086531752 0.13999999999999996 0.03196432406385705
  rotation 0 1 0 0.7853979618637926
  children [
    Shape {
      appearance PBRAppearance {
        baseColor 0.1803921568627451 0.20392156862745098 0.21176470588235294
      }
      geometry DEF OBS_1 Box {
        size 0.01 0.4 0.5
      }
    }
  ]
  name "solid(14)"
  boundingObject USE OBS_1
}
Solid {
  translation 1.3662515389142265 0.13999999999999996 0.40835702933133167
  rotation 0 1 0 3.1415925215821394
  children [
    Shape {
      appearance PBRAppearance {
        baseColor 0.1803921568627451 0.20392156862745098 0.21176470588235294
      }
      geometry DEF OBS_1 Box {
        size 0.01 0.4 0.3
      }
    }
  ]
  name "solid(15)"
  boundingObject USE OBS_1
}
Solid {
  translation 1.1969693811971516 0.13999999999999996 1.3118952988696333
  rotation 0 1 0 2.0943949352229656
  children [
    Shape {
      appearance PBRAppearance {
        baseColor 0.1803921568627451 0.20392156862745098 0.21176470588235294
      }
      geometry DEF OBS_1 Box {
        size 0.01 0.4 0.3
      }
    }
  ]
  name "solid(16)"
  boundingObject USE OBS_1
}
